2024-06-12 11:20:29,736 INFO    StreamThr :41497 [internal.py:wandb_internal():85] W&B internal server running at pid: 41497, started at: 2024-06-12 11:20:29.735942
2024-06-12 11:20:29,738 DEBUG   HandlerThread:41497 [handler.py:handle_request():158] handle_request: status
2024-06-12 11:20:29,738 INFO    WriterThread:41497 [datastore.py:open_for_write():87] open: /Users/balthazarmartin/Documents/Dev/DeepRL_test/wandb/run-20240612_112029-9hr500m4/run-9hr500m4.wandb
2024-06-12 11:20:29,741 DEBUG   SenderThread:41497 [sender.py:send():379] send: header
2024-06-12 11:20:29,741 DEBUG   SenderThread:41497 [sender.py:send():379] send: run
2024-06-12 11:20:30,029 ERROR   SenderThread:41497 [internal_api.py:execute():344] 404 response executing GraphQL.
2024-06-12 11:20:30,029 ERROR   SenderThread:41497 [internal_api.py:execute():345] {"errors":[{"message":"entity CartPole-v1 not found during upsertBucket","path":["upsertBucket"]}],"data":{"upsertBucket":null}}
2024-06-12 11:20:30,029 ERROR   SenderThread:41497 [sender.py:send_run():1009] It appears that you do not have permission to access the requested resource. Please reach out to the project owner to grant you access. If you have the correct permissions, verify that there are no issues with your networking setup.(Error 404: Not Found)
Traceback (most recent call last):
  File "/Users/balthazarmartin/Documents/Dev/DeepRL_test/.venv/lib/python3.11/site-packages/wandb/sdk/lib/retry.py", line 131, in __call__
    result = self._call_fn(*args, **kwargs)
             ^^^^^^^^^^^^^^^^^^^^^^^^^^^^^^
  File "/Users/balthazarmartin/Documents/Dev/DeepRL_test/.venv/lib/python3.11/site-packages/wandb/sdk/internal/internal_api.py", line 340, in execute
    return self.client.execute(*args, **kwargs)  # type: ignore
           ^^^^^^^^^^^^^^^^^^^^^^^^^^^^^^^^^^^^
  File "/Users/balthazarmartin/Documents/Dev/DeepRL_test/.venv/lib/python3.11/site-packages/wandb/vendor/gql-0.2.0/wandb_gql/client.py", line 52, in execute
    result = self._get_result(document, *args, **kwargs)
             ^^^^^^^^^^^^^^^^^^^^^^^^^^^^^^^^^^^^^^^^^^^
  File "/Users/balthazarmartin/Documents/Dev/DeepRL_test/.venv/lib/python3.11/site-packages/wandb/vendor/gql-0.2.0/wandb_gql/client.py", line 60, in _get_result
    return self.transport.execute(document, *args, **kwargs)
           ^^^^^^^^^^^^^^^^^^^^^^^^^^^^^^^^^^^^^^^^^^^^^^^^^
  File "/Users/balthazarmartin/Documents/Dev/DeepRL_test/.venv/lib/python3.11/site-packages/wandb/sdk/lib/gql_request.py", line 59, in execute
    request.raise_for_status()
  File "/Users/balthazarmartin/Documents/Dev/DeepRL_test/.venv/lib/python3.11/site-packages/requests/models.py", line 1024, in raise_for_status
    raise HTTPError(http_error_msg, response=self)
requests.exceptions.HTTPError: 404 Client Error: Not Found for url: https://api.wandb.ai/graphql

During handling of the above exception, another exception occurred:

Traceback (most recent call last):
  File "/Users/balthazarmartin/Documents/Dev/DeepRL_test/.venv/lib/python3.11/site-packages/wandb/sdk/internal/sender.py", line 1007, in send_run
    server_run = self._init_run(run, config_value_dict)
                 ^^^^^^^^^^^^^^^^^^^^^^^^^^^^^^^^^^^^^^
  File "/Users/balthazarmartin/Documents/Dev/DeepRL_test/.venv/lib/python3.11/site-packages/wandb/sdk/internal/sender.py", line 1079, in _init_run
    server_run, inserted, server_messages = self._api.upsert_run(
                                            ^^^^^^^^^^^^^^^^^^^^^
  File "/Users/balthazarmartin/Documents/Dev/DeepRL_test/.venv/lib/python3.11/site-packages/wandb/apis/normalize.py", line 73, in wrapper
    raise err
  File "/Users/balthazarmartin/Documents/Dev/DeepRL_test/.venv/lib/python3.11/site-packages/wandb/apis/normalize.py", line 41, in wrapper
    return func(*args, **kwargs)
           ^^^^^^^^^^^^^^^^^^^^^
  File "/Users/balthazarmartin/Documents/Dev/DeepRL_test/.venv/lib/python3.11/site-packages/wandb/sdk/internal/internal_api.py", line 2188, in upsert_run
    response = self.gql(
               ^^^^^^^^^
  File "/Users/balthazarmartin/Documents/Dev/DeepRL_test/.venv/lib/python3.11/site-packages/wandb/sdk/internal/internal_api.py", line 312, in gql
    ret = self._retry_gql(
          ^^^^^^^^^^^^^^^^
  File "/Users/balthazarmartin/Documents/Dev/DeepRL_test/.venv/lib/python3.11/site-packages/wandb/sdk/lib/retry.py", line 147, in __call__
    retry_timedelta_triggered = check_retry_fn(e)
                                ^^^^^^^^^^^^^^^^^
  File "/Users/balthazarmartin/Documents/Dev/DeepRL_test/.venv/lib/python3.11/site-packages/wandb/util.py", line 965, in check_retry_fn
    return fallback_retry_fn(e)
           ^^^^^^^^^^^^^^^^^^^^
  File "/Users/balthazarmartin/Documents/Dev/DeepRL_test/.venv/lib/python3.11/site-packages/wandb/util.py", line 907, in no_retry_auth
    raise CommError(
wandb.errors.CommError: It appears that you do not have permission to access the requested resource. Please reach out to the project owner to grant you access. If you have the correct permissions, verify that there are no issues with your networking setup.(Error 404: Not Found)
2024-06-12 11:20:30,366 DEBUG   HandlerThread:41497 [handler.py:handle_request():158] handle_request: shutdown
2024-06-12 11:20:30,366 INFO    HandlerThread:41497 [handler.py:finish():882] shutting down handler
2024-06-12 11:20:30,742 INFO    WriterThread:41497 [datastore.py:close():296] close: /Users/balthazarmartin/Documents/Dev/DeepRL_test/wandb/run-20240612_112029-9hr500m4/run-9hr500m4.wandb
2024-06-12 11:20:31,042 INFO    SenderThread:41497 [sender.py:finish():1608] shutting down sender
